<?xml version="1.0" ?>
<robot name="robot">
    <link name="link_base">
    <inertial>
      <origin xyz="0 0 0" rpy="0 0 0"/>
      <mass value="10"/>
      <inertia ixx="1" ixy="0" ixz="0" iyy="1" iyz="0" izz="1"/>
    </inertial>
        <visual>
      <origin xyz="0 0 0" rpy="0 0 0"/>
      <geometry>
        <mesh filename="$(find fish_hpurv)/meshes/assets/part_8.stl"/>
      </geometry>
      <material name="part_8_material">
        <color rgba="0.768627 0.886275 0.952941 1.0"/>
      </material>
    </visual>
    <collision>
      <origin xyz="0 0 0" rpy="0 0 0"/>
      <geometry>
        <mesh filename="$(find fish_hpurv)/meshes/assets/part_8.stl"/>
      </geometry>
    </collision>
        <visual>
      <origin xyz="0 0 0" rpy="0 0 0"/>
      <geometry>
        <mesh filename="$(find fish_hpurv)/meshes/assets/part_4.stl"/>
      </geometry>
      <material name="part_4_material">
        <color rgba="0.615686 0.811765 0.929412 1.0"/>
      </material>
    </visual>
    <collision>
      <origin xyz="0 0 0" rpy="0 0 0"/>
      <geometry>
        <mesh filename="$(find fish_hpurv)/meshes/assets/part_4.stl"/>
      </geometry>
    </collision>
        <visual>
      <origin xyz="0 0 0" rpy="0 0 0"/>
      <geometry>
        <mesh filename="$(find fish_hpurv)/meshes/assets/part_11.stl"/>
      </geometry>
      <material name="part_11_material">
        <color rgba="0.980392 0.713725 0.00392157 1.0"/>
      </material>
    </visual>
    <collision>
      <origin xyz="0 0 0" rpy="0 0 0"/>
      <geometry>
        <mesh filename="$(find fish_hpurv)/meshes/assets/part_11.stl"/>
      </geometry>
    </collision>
        <visual>
      <origin xyz="0 0 0" rpy="0 0 0"/>
      <geometry>
        <mesh filename="$(find fish_hpurv)/meshes/assets/part_5.stl"/>
      </geometry>
      <material name="part_5_material">
        <color rgba="0.647059 0.647059 0.647059 1.0"/>
      </material>
    </visual>
    <collision>
      <origin xyz="0 0 0" rpy="0 0 0"/>
      <geometry>
        <mesh filename="$(find fish_hpurv)/meshes/assets/part_5.stl"/>
      </geometry>
    </collision>
        <visual>
      <origin xyz="0 0 0" rpy="0 0 0"/>
      <geometry>
        <mesh filename="$(find fish_hpurv)/meshes/assets/part_14.stl"/>
      </geometry>
      <material name="part_14_material">
        <color rgba="0.231373 0.380392 0.705882 1.0"/>
      </material>
    </visual>
    <collision>
      <origin xyz="0 0 0" rpy="0 0 0"/>
      <geometry>
        <mesh filename="$(find fish_hpurv)/meshes/assets/part_14.stl"/>
      </geometry>
    </collision>
        <visual>
      <origin xyz="0 0 0" rpy="0 0 0"/>
      <geometry>
        <mesh filename="$(find fish_hpurv)/meshes/assets/part_7.stl"/>
      </geometry>
      <material name="part_7_material">
        <color rgba="0.917647 0.917647 0.917647 1.0"/>
      </material>
    </visual>
    <collision>
      <origin xyz="0 0 0" rpy="0 0 0"/>
      <geometry>
        <mesh filename="$(find fish_hpurv)/meshes/assets/part_7.stl"/>
      </geometry>
    </collision>
        <visual>
      <origin xyz="0 0 0" rpy="0 0 0"/>
      <geometry>
        <mesh filename="$(find fish_hpurv)/meshes/assets/part_6.stl"/>
      </geometry>
      <material name="part_6_material">
        <color rgba="0.231373 0.380392 0.705882 1.0"/>
      </material>
    </visual>
    <collision>
      <origin xyz="0 0 0" rpy="0 0 0"/>
      <geometry>
        <mesh filename="$(find fish_hpurv)/meshes/assets/part_6.stl"/>
      </geometry>
    </collision>
        <visual>
      <origin xyz="0 0 0" rpy="0 0 0"/>
      <geometry>t
        <mesh filename="$(find fish_hpurv)/meshes/assets/part_15.stl"/>
      </geometry>
      <material name="part_15_material">
        <color rgba="0.917647 0.917647 0.917647 1.0"/>
      </material>
    </visual>
    <collision>
      <origin xyz="0 0 0" rpy="0 0 0"/>
      <geometry>
        <mesh filename="$(find fish_hpurv)/meshes/assets/part_15.stl"/>
      </geometry>
    </collision>
        <visual>
      <origin xyz="0 0 0" rpy="0 0 0"/>
      <geometry>
        <mesh filename="$(find fish_hpurv)/meshes/assets/part_9.stl"/>
      </geometry>
      <material name="part_9_material">
        <color rgba="0.972549 0.529412 0.00392157 1.0"/>
      </material>
    </visual>
    <collision>
      <origin xyz="0 0 0" rpy="0 0 0"/>
      <geometry>
        <mesh filename="$(find fish_hpurv)/meshes/assets/part_9.stl"/>
      </geometry>
    </collision>
        <visual>
      <origin xyz="0 0 0" rpy="0 0 0"/>
      <geometry>
        <mesh filename="$(find fish_hpurv)/meshes/assets/part_13.stl"/>
      </geometry>
      <material name="part_13_material">
        <color rgba="0.647059 0.647059 0.647059 1.0"/>
      </material>
    </visual>
    <collision>
      <origin xyz="0 0 0" rpy="0 0 0"/>
      <geometry>
        <mesh filename="$(find fish_hpurv)/meshes/assets/part_13.stl"/>
      </geometry>
    </collision>
  </link>
    <link name="link_hip_l">
    <inertial>
      <origin xyz="0 0 0" rpy="0 0 0"/>
      <mass value="10"/>
      <inertia ixx="1" ixy="0" ixz="0" iyy="1" iyz="0" izz="1"/>
    </inertial>
        <visual>
      <origin xyz="0 0 0" rpy="0 0 0"/>
      <geometry>
        <mesh filename="$(find fish_hpurv)/meshes/assets/part_2.stl"/>
      </geometry>
      <material name="part_2_material">
        <color rgba="0.231373 0.380392 0.705882 1.0"/>
      </material>
    </visual>
    <collision>
      <origin xyz="0 0 0" rpy="0 0 0"/>
      <geometry>
        <mesh filename="$(find fish_hpurv)/meshes/assets/part_2.stl"/>
      </geometry>
    </collision>
        <visual>
      <origin xyz="0 0 0" rpy="0 0 0"/>
      <geometry>
        <mesh filename="$(find fish_hpurv)/meshes/assets/part_1.stl"/>
      </geometry>
      <material name="part_1_material">
        <color rgba="0.647059 0.647059 0.647059 1.0"/>
      </material>
    </visual>
    <collision>
      <origin xyz="0 0 0" rpy="0 0 0"/>
      <geometry>
        <mesh filename="$(find fish_hpurv)/meshes/assets/part_1.stl"/>
      </geometry>
    </collision>
  </link>
    <joint name="joint12" type="continuous">
    <origin xyz="0 0 0.2" rpy="0 0 0"/>
    <parent link="link_base"/>
    <child link="link_hip_l"/>
    <axis xyz="0 0 1"/>
  </joint>
</robot>