<?xml version="1.0" ?>
<robot name="robot">
    <link name="link_base">
    <inertial>
      <origin xyz="0 0 0" rpy="0 0 0"/>
      <mass value="10"/>
      <inertia ixx="1" ixy="0" ixz="0" iyy="1" iyz="0" izz="1"/>
    </inertial>
        <visual>
      <origin xyz="0 0 0" rpy="0 0 0"/>
      <geometry>
        <mesh filename="$(find robot)/mesh/assets/part_8.stl"/>
      </geometry>
      <material name="part_8_material">
        <color rgba="0.768627 0.886275 0.952941 1.0"/>
      </material>
    </visual>
    <collision>
      <origin xyz="0 0 0" rpy="0 0 0"/>
      <geometry>
        <mesh filename="$(find robot)/mesh/assets/part_8.stl"/>
      </geometry>
    </collision>
        <visual>
      <origin xyz="0 0 0" rpy="0 0 0"/>
      <geometry>
        <mesh filename="$(find robot)/mesh/assets/part_4.stl"/>
      </geometry>
      <material name="part_4_material">
        <color rgba="0.615686 0.811765 0.929412 1.0"/>
      </material>
    </visual>
    <collision>
      <origin xyz="0 0 0" rpy="0 0 0"/>
      <geometry>
        <mesh filename="$(find robot)/mesh/assets/part_4.stl"/>
      </geometry>
    </collision>
        <visual>
      <origin xyz="0 0 0" rpy="0 0 0"/>
      <geometry>
        <mesh filename="$(find robot)/mesh/assets/part_11.stl"/>
      </geometry>
      <material name="part_11_material">
        <color rgba="0.980392 0.713725 0.00392157 1.0"/>
      </material>
    </visual>
    <collision>
      <origin xyz="0 0 0" rpy="0 0 0"/>
      <geometry>
        <mesh filename="$(find robot)/mesh/assets/part_11.stl"/>
      </geometry>
    </collision>
        <visual>
      <origin xyz="0 0 0" rpy="0 0 0"/>
      <geometry>
        <mesh filename="$(find robot)/mesh/assets/part_5.stl"/>
      </geometry>
      <material name="part_5_material">
        <color rgba="0.647059 0.647059 0.647059 1.0"/>
      </material>
    </visual>
    <collision>
      <origin xyz="0 0 0" rpy="0 0 0"/>
      <geometry>
        <mesh filename="$(find robot)/mesh/assets/part_5.stl"/>
      </geometry>
    </collision>
        <visual>
      <origin xyz="0 0 0" rpy="0 0 0"/>
      <geometry>
        <mesh filename="$(find robot)/mesh/assets/part_14.stl"/>
      </geometry>
      <material name="part_14_material">
        <color rgba="0.231373 0.380392 0.705882 1.0"/>
      </material>
    </visual>
    <collision>
      <origin xyz="0 0 0" rpy="0 0 0"/>
      <geometry>
        <mesh filename="$(find robot)/mesh/assets/part_14.stl"/>
      </geometry>
    </collision>
        <visual>
      <origin xyz="0 0 0" rpy="0 0 0"/>
      <geometry>
        <mesh filename="$(find robot)/mesh/assets/part_7.stl"/>
      </geometry>
      <material name="part_7_material">
        <color rgba="0.917647 0.917647 0.917647 1.0"/>
      </material>
    </visual>
    <collision>
      <origin xyz="0 0 0" rpy="0 0 0"/>
      <geometry>
        <mesh filename="$(find robot)/mesh/assets/part_7.stl"/>
      </geometry>
    </collision>
        <visual>
      <origin xyz="0 0 0" rpy="0 0 0"/>
      <geometry>
        <mesh filename="$(find robot)/mesh/assets/part_6.stl"/>
      </geometry>
      <material name="part_6_material">
        <color rgba="0.231373 0.380392 0.705882 1.0"/>
      </material>
    </visual>
    <collision>
      <origin xyz="0 0 0" rpy="0 0 0"/>
      <geometry>
        <mesh filename="$(find robot)/mesh/assets/part_6.stl"/>
      </geometry>
    </collision>
        <visual>
      <origin xyz="0 0 0" rpy="0 0 0"/>
      <geometry>t
        <mesh filename="$(find robot)/mesh/assets/part_15.stl"/>
      </geometry>
      <material name="part_15_material">
        <color rgba="0.917647 0.917647 0.917647 1.0"/>
      </material>
    </visual>
    <collision>
      <origin xyz="0 0 0" rpy="0 0 0"/>
      <geometry>
        <mesh filename="$(find robot)/mesh/assets/part_15.stl"/>
      </geometry>
    </collision>
        <visual>
      <origin xyz="0 0 0" rpy="0 0 0"/>
      <geometry>
        <mesh filename="$(find robot)/mesh/assets/part_9.stl"/>
      </geometry>
      <material name="part_9_material">
        <color rgba="0.972549 0.529412 0.00392157 1.0"/>
      </material>
    </visual>
    <collision>
      <origin xyz="0 0 0" rpy="0 0 0"/>
      <geometry>
        <mesh filename="$(find robot)/mesh/assets/part_9.stl"/>
      </geometry>
    </collision>
        <visual>
      <origin xyz="0 0 0" rpy="0 0 0"/>
      <geometry>
        <mesh filename="$(find robot)/mesh/assets/part_13.stl"/>
      </geometry>
      <material name="part_13_material">
        <color rgba="0.647059 0.647059 0.647059 1.0"/>
      </material>
    </visual>
    <collision>
      <origin xyz="0 0 0" rpy="0 0 0"/>
      <geometry>
        <mesh filename="$(find robot)/mesh/assets/part_13.stl"/>
      </geometry>
    </collision>
  </link>
    <link name="link_hip">
    <inertial>
      <origin xyz="0 0 0" rpy="0 0 0"/>
      <mass value="10"/>
      <inertia ixx="1" ixy="0" ixz="0" iyy="1" iyz="0" izz="1"/>
    </inertial>
        <visual>
      <origin xyz="0 0 0" rpy="0 0 0"/>
      <geometry>
        <mesh filename="$(find robot)/mesh/assets/part_2.stl"/>
      </geometry>
      <material name="part_2_material">
        <color rgba="0.231373 0.380392 0.705882 1.0"/>
      </material>
    </visual>
    <collision>
      <origin xyz="0 0 0" rpy="0 0 0"/>
      <geometry>
        <mesh filename="$(find robot)/mesh/assets/part_2.stl"/>
      </geometry>
    </collision>
        <visual>
      <origin xyz="0 0 0" rpy="0 0 0"/>
      <geometry>
        <mesh filename="$(find robot)/mesh/assets/part_1.stl"/>
      </geometry>
      <material name="part_1_material">
        <color rgba="0.647059 0.647059 0.647059 1.0"/>
      </material>
    </visual>
    <collision>
      <origin xyz="0 0 0" rpy="0 0 0"/>
      <geometry>
        <mesh filename="$(find robot)/mesh/assets/part_1.stl"/>
      </geometry>
    </collision>
  </link>
    <link name="link_hip_2">
    <inertial>
      <origin xyz="0 0 0" rpy="0 0 0"/>
      <mass value="10"/>
      <inertia ixx="1" ixy="0" ixz="0" iyy="1" iyz="0" izz="1"/>
    </inertial>
        <visual>
      <origin xyz="0 0 0" rpy="0 0 0"/>
      <geometry>
        <mesh filename="$(find robot)/mesh/assets/part_2.stl"/>
      </geometry>
      <material name="part_2_2_material">
        <color rgba="0.231373 0.380392 0.705882 1.0"/>
      </material>
    </visual>
    <collision>
      <origin xyz="0 0 0" rpy="0 0 0"/>
      <geometry>
        <mesh filename="$(find robot)/mesh/assets/part_2.stl"/>
      </geometry>
    </collision>
        <visual>
      <origin xyz="0 0 0" rpy="0 0 0"/>
      <geometry>
        <mesh filename="$(find robot)/mesh/assets/part_1.stl"/>
      </geometry>
      <material name="part_1_2_material">
        <color rgba="0.647059 0.647059 0.647059 1.0"/>
      </material>
    </visual>
    <collision>
      <origin xyz="0 0 0" rpy="0 0 0"/>
      <geometry>
        <mesh filename="$(find robot)/mesh/assets/part_1.stl"/>
      </geometry>
    </collision>
  </link>
    <link name="link_thigh">
    <inertial>
      <origin xyz="0 0 0" rpy="0 0 0"/>
      <mass value="10"/>
      <inertia ixx="1" ixy="0" ixz="0" iyy="1" iyz="0" izz="1"/>
    </inertial>
        <visual>
      <origin xyz="0 0 0" rpy="0 0 0"/>
      <geometry>
        <mesh filename="$(find robot)/mesh/assets/part_3.stl"/>
      </geometry>
      <material name="part_3_material">
        <color rgba="0.231373 0.380392 0.705882 1.0"/>
      </material>
    </visual>
    <collision>
      <origin xyz="0 0 0" rpy="0 0 0"/>
      <geometry>
        <mesh filename="$(find robot)/mesh/assets/part_3.stl"/>
      </geometry>
    </collision>
        <visual>
      <origin xyz="0 0 0" rpy="0 0 0"/>
      <geometry>
        <mesh filename="$(find robot)/mesh/assets/part_2__2.stl"/>
      </geometry>
      <material name="part_2_3_material">
        <color rgba="0.647059 0.647059 0.647059 1.0"/>
      </material>
    </visual>
    <collision>
      <origin xyz="0 0 0" rpy="0 0 0"/>
      <geometry>
        <mesh filename="$(find robot)/mesh/assets/part_2__2.stl"/>
      </geometry>
    </collision>
        <visual>
      <origin xyz="0 0 0" rpy="0 0 0"/>
      <geometry>
        <mesh filename="$(find robot)/mesh/assets/part_6__2.stl"/>
      </geometry>
      <material name="part_6_2_material">
        <color rgba="0.972549 0.529412 0.00392157 1.0"/>
      </material>
    </visual>
    <collision>
      <origin xyz="0 0 0" rpy="0 0 0"/>
      <geometry>
        <mesh filename="$(find robot)/mesh/assets/part_6__2.stl"/>
      </geometry>
    </collision>
        <visual>
      <origin xyz="0 0 0" rpy="0 0 0"/>
      <geometry>
        <mesh filename="$(find robot)/mesh/assets/part_4__2.stl"/>
      </geometry>
      <material name="part_4_2_material">
        <color rgba="0.917647 0.917647 0.917647 1.0"/>
      </material>
    </visual>
    <collision>
      <origin xyz="0 0 0" rpy="0 0 0"/>
      <geometry>
        <mesh filename="$(find robot)/mesh/assets/part_4__2.stl"/>
      </geometry>
    </collision>
        <visual>
      <origin xyz="0 0 0" rpy="0 0 0"/>
      <geometry>
        <mesh filename="$(find robot)/mesh/assets/part_5__2.stl"/>
      </geometry>
      <material name="part_5_2_material">
        <color rgba="0.768627 0.886275 0.952941 1.0"/>
      </material>
    </visual>
    <collision>
      <origin xyz="0 0 0" rpy="0 0 0"/>
      <geometry>
        <mesh filename="$(find robot)/mesh/assets/part_5__2.stl"/>
      </geometry>
    </collision>
  </link>
    <joint name="joint6" type="revolute">
    <origin xyz="0 0 0" rpy="0 0 0"/>
    <parent link="link_hip_2"/>
    <child link="link_thigh"/>
    <axis xyz="0 0 1"/>
    <limit effort="10" velocity="10" lower="-3.141592653589793" upper="3.141592653589793"/>
  </joint>
    <joint name="joint3" type="revolute">
    <origin xyz="0 0 0" rpy="0 0 0"/>
    <parent link="link_hip"/>
    <child link="link_hip_2"/>
    <axis xyz="0 0 1"/>
    <limit effort="10" velocity="10" lower="-3.141592653589793" upper="3.141592653589793"/>
  </joint>
    <link name="link_thing_r">
    <inertial>
      <origin xyz="0 0 0" rpy="0 0 0"/>
      <mass value="10"/>
      <inertia ixx="1" ixy="0" ixz="0" iyy="1" iyz="0" izz="1"/>
    </inertial>
        <visual>
      <origin xyz="0 0 0" rpy="0 0 0"/>
      <geometry>
        <mesh filename="$(find robot)/mesh/assets/part_4__3.stl"/>
      </geometry>
      <material name="part_4_3_material">
        <color rgba="0.231373 0.380392 0.705882 1.0"/>
      </material>
    </visual>
    <collision>
      <origin xyz="0 0 0" rpy="0 0 0"/>
      <geometry>
        <mesh filename="$(find robot)/mesh/assets/part_4__3.stl"/>
      </geometry>
    </collision>
        <visual>
      <origin xyz="0 0 0" rpy="0 0 0"/>
      <geometry>
        <mesh filename="$(find robot)/mesh/assets/part_7__2.stl"/>
      </geometry>
      <material name="part_7_2_material">
        <color rgba="0.972549 0.529412 0.00392157 1.0"/>
      </material>
    </visual>
    <collision>
      <origin xyz="0 0 0" rpy="0 0 0"/>
      <geometry>
        <mesh filename="$(find robot)/mesh/assets/part_7__2.stl"/>
      </geometry>
    </collision>
        <visual>
      <origin xyz="0 0 0" rpy="0 0 0"/>
      <geometry>
        <mesh filename="$(find robot)/mesh/assets/part_3__2.stl"/>
      </geometry>
      <material name="part_3_2_material">
        <color rgba="0.647059 0.647059 0.647059 1.0"/>
      </material>
    </visual>
    <collision>
      <origin xyz="0 0 0" rpy="0 0 0"/>
      <geometry>
        <mesh filename="$(find robot)/mesh/assets/part_3__2.stl"/>
      </geometry>
    </collision>
        <visual>
      <origin xyz="0 0 0" rpy="0 0 0"/>
      <geometry>
        <mesh filename="$(find robot)/mesh/assets/part_6__3.stl"/>
      </geometry>
      <material name="part_6_3_material">
        <color rgba="0.768627 0.886275 0.952941 1.0"/>
      </material>
    </visual>
    <collision>
      <origin xyz="0 0 0" rpy="0 0 0"/>
      <geometry>
        <mesh filename="$(find robot)/mesh/assets/part_6__3.stl"/>
      </geometry>
    </collision>
        <visual>
      <origin xyz="0 0 0" rpy="0 0 0"/>
      <geometry>
        <mesh filename="$(find robot)/mesh/assets/part_5__3.stl"/>
      </geometry>
      <material name="part_5_3_material">
        <color rgba="0.917647 0.917647 0.917647 1.0"/>
      </material>
    </visual>
    <collision>
      <origin xyz="0 0 0" rpy="0 0 0"/>
      <geometry>
        <mesh filename="$(find robot)/mesh/assets/part_5__3.stl"/>
      </geometry>
    </collision>
  </link>
    <joint name="joint8" type="revolute">
    <origin xyz="0 0 0" rpy="0 0 0"/>
    <parent link="link_hip"/>
    <child link="link_thing_r"/>
    <axis xyz="0 0 1"/>
    <limit effort="10" velocity="10" lower="-3.141592653589793" upper="3.141592653589793"/>
  </joint>
    <joint name="joint1" type="revolute">
    <origin xyz="0 0 0" rpy="0 0 0"/>
    <parent link="link_base"/>
    <child link="link_hip"/>
    <axis xyz="0 0 1"/>
    <limit effort="10" velocity="10" lower="-3.141592653589793" upper="3.141592653589793"/>
  </joint>
    <link name="link_hip_3">
    <inertial>
      <origin xyz="0 0 0" rpy="0 0 0"/>
      <mass value="10"/>
      <inertia ixx="1" ixy="0" ixz="0" iyy="1" iyz="0" izz="1"/>
    </inertial>
        <visual>
      <origin xyz="0 0 0" rpy="0 0 0"/>
      <geometry>
        <mesh filename="$(find robot)/mesh/assets/part_2.stl"/>
      </geometry>
      <material name="part_2_4_material">
        <color rgba="0.231373 0.380392 0.705882 1.0"/>
      </material>
    </visual>
    <collision>
      <origin xyz="0 0 0" rpy="0 0 0"/>
      <geometry>
        <mesh filename="$(find robot)/mesh/assets/part_2.stl"/>
      </geometry>
    </collision>
        <visual>
      <origin xyz="0 0 0" rpy="0 0 0"/>
      <geometry>
        <mesh filename="$(find robot)/mesh/assets/part_1.stl"/>
      </geometry>
      <material name="part_1_3_material">
        <color rgba="0.647059 0.647059 0.647059 1.0"/>
      </material>
    </visual>
    <collision>
      <origin xyz="0 0 0" rpy="0 0 0"/>
      <geometry>
        <mesh filename="$(find robot)/mesh/assets/part_1.stl"/>
      </geometry>
    </collision>
  </link>
    <link name="link_thing_r_2">
    <inertial>
      <origin xyz="0 0 0" rpy="0 0 0"/>
      <mass value="10"/>
      <inertia ixx="1" ixy="0" ixz="0" iyy="1" iyz="0" izz="1"/>
    </inertial>
        <visual>
      <origin xyz="0 0 0" rpy="0 0 0"/>
      <geometry>
        <mesh filename="$(find robot)/mesh/assets/part_4__3.stl"/>
      </geometry>
      <material name="part_4_4_material">
        <color rgba="0.231373 0.380392 0.705882 1.0"/>
      </material>
    </visual>
    <collision>
      <origin xyz="0 0 0" rpy="0 0 0"/>
      <geometry>
        <mesh filename="$(find robot)/mesh/assets/part_4__3.stl"/>
      </geometry>
    </collision>
        <visual>
      <origin xyz="0 0 0" rpy="0 0 0"/>
      <geometry>
        <mesh filename="$(find robot)/mesh/assets/part_7__2.stl"/>
      </geometry>
      <material name="part_7_3_material">
        <color rgba="0.972549 0.529412 0.00392157 1.0"/>
      </material>
    </visual>
    <collision>
      <origin xyz="0 0 0" rpy="0 0 0"/>
      <geometry>
        <mesh filename="$(find robot)/mesh/assets/part_7__2.stl"/>
      </geometry>
    </collision>
        <visual>
      <origin xyz="0 0 0" rpy="0 0 0"/>
      <geometry>
        <mesh filename="$(find robot)/mesh/assets/part_3__2.stl"/>
      </geometry>
      <material name="part_3_3_material">
        <color rgba="0.647059 0.647059 0.647059 1.0"/>
      </material>
    </visual>
    <collision>
      <origin xyz="0 0 0" rpy="0 0 0"/>
      <geometry>
        <mesh filename="$(find robot)/mesh/assets/part_3__2.stl"/>
      </geometry>
    </collision>
        <visual>
      <origin xyz="0 0 0" rpy="0 0 0"/>
      <geometry>
        <mesh filename="$(find robot)/mesh/assets/part_6__3.stl"/>
      </geometry>
      <material name="part_6_4_material">
        <color rgba="0.768627 0.886275 0.952941 1.0"/>
      </material>
    </visual>
    <collision>
      <origin xyz="0 0 0" rpy="0 0 0"/>
      <geometry>
        <mesh filename="$(find robot)/mesh/assets/part_6__3.stl"/>
      </geometry>
    </collision>
        <visual>
      <origin xyz="0 0 0" rpy="0 0 0"/>
      <geometry>
        <mesh filename="$(find robot)/mesh/assets/part_5__3.stl"/>
      </geometry>
      <material name="part_5_4_material">
        <color rgba="0.917647 0.917647 0.917647 1.0"/>
      </material>
    </visual>
    <collision>
      <origin xyz="0 0 0" rpy="0 0 0"/>
      <geometry>
        <mesh filename="$(find robot)/mesh/assets/part_5__3.stl"/>
      </geometry>
    </collision>
  </link>
    <joint name="joint7" type="revolute">
    <origin xyz="0 0 0" rpy="0 0 0"/>
    <parent link="link_hip_3"/>
    <child link="link_thing_r_2"/>
    <axis xyz="0 0 1"/>
    <limit effort="10" velocity="10" lower="-3.141592653589793" upper="3.141592653589793"/>
  </joint>
    <joint name="joint2" type="revolute">
    <origin xyz="0 0 0" rpy="0 0 0"/>
    <parent link="link_base"/>
    <child link="link_hip_3"/>
    <axis xyz="0 0 1"/>
    <limit effort="10" velocity="10" lower="-3.141592653589793" upper="3.141592653589793"/>
  </joint>
    <link name="link_hip_4">
    <inertial>
      <origin xyz="0 0 0" rpy="0 0 0"/>
      <mass value="10"/>
      <inertia ixx="1" ixy="0" ixz="0" iyy="1" iyz="0" izz="1"/>
    </inertial>
        <visual>
      <origin xyz="0 0 0" rpy="0 0 0"/>
      <geometry>
        <mesh filename="$(find robot)/mesh/assets/part_2.stl"/>
      </geometry>
      <material name="part_2_5_material">
        <color rgba="0.231373 0.380392 0.705882 1.0"/>
      </material>
    </visual>
    <collision>
      <origin xyz="0 0 0" rpy="0 0 0"/>
      <geometry>
        <mesh filename="$(find robot)/mesh/assets/part_2.stl"/>
      </geometry>
    </collision>
        <visual>
      <origin xyz="0 0 0" rpy="0 0 0"/>
      <geometry>
        <mesh filename="$(find robot)/mesh/assets/part_1.stl"/>
      </geometry>
      <material name="part_1_4_material">
        <color rgba="0.647059 0.647059 0.647059 1.0"/>
      </material>
    </visual>
    <collision>
      <origin xyz="0 0 0" rpy="0 0 0"/>
      <geometry>
        <mesh filename="$(find robot)/mesh/assets/part_1.stl"/>
      </geometry>
    </collision>
  </link>
    <link name="link_thigh_2">
    <inertial>
      <origin xyz="0 0 0" rpy="0 0 0"/>
      <mass value="10"/>
      <inertia ixx="1" ixy="0" ixz="0" iyy="1" iyz="0" izz="1"/>
    </inertial>
        <visual>
      <origin xyz="0 0 0" rpy="0 0 0"/>
      <geometry>
        <mesh filename="$(find robot)/mesh/assets/part_3.stl"/>
      </geometry>
      <material name="part_3_4_material">
        <color rgba="0.231373 0.380392 0.705882 1.0"/>
      </material>
    </visual>
    <collision>
      <origin xyz="0 0 0" rpy="0 0 0"/>
      <geometry>
        <mesh filename="$(find robot)/mesh/assets/part_3.stl"/>
      </geometry>
    </collision>
        <visual>
      <origin xyz="0 0 0" rpy="0 0 0"/>
      <geometry>
        <mesh filename="$(find robot)/mesh/assets/part_2__2.stl"/>
      </geometry>
      <material name="part_2_6_material">
        <color rgba="0.647059 0.647059 0.647059 1.0"/>
      </material>
    </visual>
    <collision>
      <origin xyz="0 0 0" rpy="0 0 0"/>
      <geometry>
        <mesh filename="$(find robot)/mesh/assets/part_2__2.stl"/>
      </geometry>
    </collision>
        <visual>
      <origin xyz="0 0 0" rpy="0 0 0"/>
      <geometry>
        <mesh filename="$(find robot)/mesh/assets/part_6__2.stl"/>
      </geometry>
      <material name="part_6_5_material">
        <color rgba="0.972549 0.529412 0.00392157 1.0"/>
      </material>
    </visual>
    <collision>
      <origin xyz="0 0 0" rpy="0 0 0"/>
      <geometry>
        <mesh filename="$(find robot)/mesh/assets/part_6__2.stl"/>
      </geometry>
    </collision>
        <visual>
      <origin xyz="0 0 0" rpy="0 0 0"/>
      <geometry>
        <mesh filename="$(find robot)/mesh/assets/part_4__2.stl"/>
      </geometry>
      <material name="part_4_5_material">
        <color rgba="0.917647 0.917647 0.917647 1.0"/>
      </material>
    </visual>
    <collision>
      <origin xyz="0 0 0" rpy="0 0 0"/>
      <geometry>
        <mesh filename="$(find robot)/mesh/assets/part_4__2.stl"/>
      </geometry>
    </collision>
        <visual>
      <origin xyz="0 0 0" rpy="0 0 0"/>
      <geometry>
        <mesh filename="$(find robot)/mesh/assets/part_5__2.stl"/>
      </geometry>
      <material name="part_5_5_material">
        <color rgba="0.768627 0.886275 0.952941 1.0"/>
      </material>
    </visual>
    <collision>
      <origin xyz="0 0 0" rpy="0 0 0"/>
      <geometry>
        <mesh filename="$(find robot)/mesh/assets/part_5__2.stl"/>
      </geometry>
    </collision>
  </link>
    <joint name="joint5" type="revolute">
    <origin xyz="0 0 0" rpy="0 0 0"/>
    <parent link="link_hip_4"/>
    <child link="link_thigh_2"/>
    <axis xyz="0 0 1"/>
    <limit effort="10" velocity="10" lower="-3.141592653589793" upper="3.141592653589793"/>
  </joint>
    <joint name="joint4" type="revolute">
    <origin xyz="0 0 0" rpy="0 0 0"/>
    <parent link="link_base"/>
    <child link="link_hip_4"/>
    <axis xyz="0 0 1"/>
    <limit effort="10" velocity="10" lower="-3.141592653589793" upper="3.141592653589793"/>
  </joint>
</robot>